Workbook

Sheet Historicals
A1: MSFT — Historical Financials (yfinance · Python-Generated)
A2: Do not edit — regenerate by running export_to_excel.py
A4: Year | B4: Revenue | C4: Gross Profit | D4: EBIT | E4: Net Income | F4: Gross Margin | G4: EBIT Margin | H4: Tax Rate | I4: D&A | J4: CapEx | K4: Free Cash Flow | L4: Total Debt | M4: Cash | N4: Net WC | O4: Cash + ST Inv
A5: 2021 | B5: 168088000000 | C5: 115856000000 | D5: 69916000000 | E5: 61271000000 | F5: 0.68925801 | G5: 0.41594879 | H5: 0.13826615 | I5: 11689000000 | J5: 20622000000 | K5: 56118000000 | L5: 67775000000 | M5: 14224000000 | N5: 95749000000 | O5: 130334000000
A6: 2022 | B6: 198270000000 | C6: 135620000000 | D6: 83383000000 | E6: 72738000000 | F6: 0.68401674 | G6: 0.42055278 | H6: 0.13113383 | I6: 14460000000 | J6: 23886000000 | K6: 65149000000 | L6: 61270000000 | M6: 13931000000 | N6: 74602000000 | O6: 104749000000
A7: 2023 | B7: 211915000000 | C7: 146052000000 | D7: 88523000000 | E7: 72361000000 | F7: 0.68920086 | G7: 0.41772881 | H7: 0.18978625 | I7: 13861000000 | J7: 28107000000 | K7: 59475000000 | L7: 59965000000 | M7: 34704000000 | N7: 80108000000 | O7: 111256000000
A8: 2024 | B8: 245122000000 | C8: 171008000000 | D8: 109433000000 | E8: 88136000000 | F8: 0.69764444 | G8: 0.446443 | H8: 0.18231327 | I8: 20958000000 | J8: 44477000000 | K8: 74071000000 | L8: 67127000000 | M8: 18315000000 | N8: 34448000000 | O8: 75531000000
A9: 2025 | B9: 281724000000 | C9: 193893000000 | D9: 128528000000 | E9: 101832000000 | F9: 0.68823742 | G9: 0.45621956 | H9: 0.17629644 | I9: 29433000000 | J9: 64551000000 | K9: 71611000000 | L9: 60588000000 | M9: 30242000000 | N9: 49913000000 | O9: 94555000000
A10: 2026 | B10: 331839000000 | C10: 225465000000 | D10: 155237000000 | E10: 133749000000 | F10: 0.67944093 | G10: 0.46780818 | H10: 0.19396266 | I10: 38534000000 | J10: 115948000000 | K10: 66987000000 | L10: 56826000000 | M10: 20935000000 | N10: 38885000000 | O10: 76651000000
I16: D&A
H17: 2024 | I17: =I8/B8 -> 0.085500281
H18: 2025 | I18: =I9/B9 -> 0.10447459
H19: 2026 | I19: =I10/B10 -> 0.11612258
H21: 3yr Average: | I21: =AVERAGE(I17:I19) -> 0.10203248

Sheet Profile
A1: MSFT — Company Profile (via yfinance)
A3: Company | B3: Microsoft Corporation
A4: Sector | B4: Technology
A5: Beta | B5: 1.099
A6: Shares Outstanding | B6: 7425545491
A7: Market Cap | B7: 3954845417472
A8: Current Price | B8: 532.6
A9: 52w High | B9: 553.72
A10: 52w Low | B10: 349.2
A11: As of | B11: 10/26/2026 close (Yahoo Finance)

Sheet Assumptions
A1: MSFT DCF Model - Assumptions
A2: Values in USD - fiscal year ending June 30 | Data Pulled From Alpha Spread, StockTitan, CNBC
A3: CapEx modeled as a glide path rather than flat assumption. FY2026A came in at 34.9% of revenue (vs 30% modeled in April), so the April glide path is shifted one year later.
A4: REVENUE GROWTH ASSUMPTIONS
A5: Revenue Growth - FY2027E | B5: 0.17 | C5: Apr-2026 FY2027E assumption (Alpha Spread 3yr CAGR); FY2026A was 17.8%
A6: Revenue Growth - FY2028E | B6: 0.15 | C6: Interpolation
A7: Revenue Growth - FY2029E | B7: 0.13 | C7: Interpolation
A8: Revenue Growth - FY2030E | B8: 0.12 | C8: Interpolation
A9: Revenue Growth - FY2031E | B9: 0.11 | C9: Interpolation (extends taper one year)
A11: MARGIN ASSUMPTIONS
A12: Gross Margin % | B12: =Historicals!F10 -> 0.67944093 | C12: FY2026 Historicals
A13: EBIT Margin % | B13: =Historicals!G10 -> 0.46780818 | C13: FY2026 Historicals
A14: Tax Rate | B14: =Historicals!H10 -> 0.19396266 | C14: FY2026 actual effective rate
A16: CASH FLOW ASSUMPTIONS
A17: D&A as % of Revenue | B17: =Historicals!I21 -> 0.10203248 | C17: 3yr avg FY2024-FY2026
A18: CapEx as % of Revenue (2027E-2031E) | B18: 0.3 | C18: 0.24 | D18: 0.18 | E18: 0.14 | F18: 0.11 | G18: FY2026A 34.9% (Q4 FY2026 alone 39.8%); April glide path (30/24/18/14/11) shifted one year; pre-AI steady state ~13% (FY2023)
A19: Change NWC as % of Rev Change | B19: 0.03 | C19: Assumption. Historical NWC changes swing from -$46B to +$16B because current assets include cash and investments, so they don't give a usable average
A21: WACC INPUTS
A22: Risk-Free Rate | B22: 0.0499 | C22: 10Y Treasury yield, 10/26/26
A23: Equity Risk Premium | B23: 0.0418 | C23: Alpha Spread
A24: Beta | B24: =Profile!B5 -> 1.099 | C24: Yahoo Finance, 10/26/26 (was 1.107 in April)
A25: Cost of Equity | B25: =B22+B24*B23 -> 0.0958382 | C25: CAPM
A26: Pre-tax Cost of Debt | B26: =B22+0.004 -> 0.0539 | C26: 10Y Treasury + ~40bp (AAA-rated; approx.). Was 3.5%, below the risk-free rate
A27: After-tax Cost of Debt | B27: =B26*(1-B14) -> 0.043445413 | C27: Pre-tax cost of debt * (1 - tax rate)
A28: Debt Weight | B28: =B47/(B47+Profile!B7) -> 0.026315858 | C28: Market value: debt incl. finance leases / (debt + market cap)
A29: Equity Rate | B29: =1-B28 -> 0.97368414 | C29: 1 - Debt Weight
A30: WACC | B30: =B29*B25+B28*B27 -> 0.094459439 | C30: (Equity Rate * Cost of Equity) + (Debt Weight * After-tax Cost of Debt)
A32: TERMINAL VALUE INPUTS
A33: Terminal Growth Rate | B33: 0.03 | C33: Long-run nominal GDP
A35: SHARES & PRICE
A36: Diluted Shares Outstanding | B36: =Profile!B6+B50 -> 7449545491 | C36: Basic shares (Yahoo, 10/26/26) + FY2026 dilution
A37: Current Stock Price | B37: =Profile!B8 -> 532.6 | C37: Yahoo Finance close, 10/26/26
A39: VALUATION TIMING
A40: Valuation Date | B40: 46321 | C40: Price date
A41: FY2027 Year End | B41: 46568 | C41: Fiscal year ends June 30
A42: Stub Fraction (FY2027E) | B42: =(B41-B40)/365 -> 0.67671233 | C42: Share of FY2027E cash flow still ahead of the valuation date
A44: BALANCE SHEET (FY2026 10-K, 6/30/2026)
A45: Long-Term Debt (incl. current portion) | B45: 40294000000 | C45: 10-K: LongTermDebt
A46: Finance Lease Liabilities | B46: 66594000000 | C46: 10-K lease note; Yahoo 'Total Debt' only includes $16.5B of this
A47: Total Debt incl. Finance Leases | B47: =B45+B46 -> 106888000000 | C47: Operating leases excluded (their cost is in EBIT)
...

Sheet Forecast
A1: MSFT DCF Model - Forecast
A2: Values in USD - fiscal year ending June 30
B4: FY2022 | C4: FY2023 | D4: FY2024 | E4: FY2025 | F4: FY2026 | G4: FY2027E | H4: FY2028E | I4: FY2029E | J4: FY2030E | K4: FY2031E
A5: Revenue | B5: =Historicals!B6 -> 198270000000 | C5: =Historicals!B7 -> 211915000000 | D5: =Historicals!B8 -> 245122000000 | E5: =Historicals!B9 -> 281724000000 | F5: =Historicals!B10 -> 331839000000 | G5: =F5*(1 + Assumptions!B5) -> 388251630000 | H5: =G5*(1+Assumptions!B6) -> 4.4648937e+11 | I5: =H5*(1+Assumptions!B7) -> 5.0453299e+11 | J5: =I5*(1+Assumptions!B8) -> 5.6507695e+11 | K5: =J5*(1+Assumptions!B9) -> 6.2723542e+11
A6: Revenue Growth % | B6: =B5/Historicals!B5-1 -> 0.17956071 | C6: =C5/B5-1 -> 0.068820296 | D6: =D5/C5-1 -> 0.15669962 | E6: =E5/D5-1 -> 0.14932156 | F6: =F5/E5-1 -> 0.17788687 | G6: =Assumptions!$B$5 -> 0.17 | H6: =Assumptions!$B$6 -> 0.15 | I6: =Assumptions!$B$7 -> 0.13 | J6: =Assumptions!$B$8 -> 0.12 | K6: =Assumptions!$B$9 -> 0.11
A7: Gross Profit | B7: =Historicals!C6 -> 135620000000 | C7: =Historicals!C7 -> 146052000000 | D7: =Historicals!C8 -> 171008000000 | E7: =Historicals!C9 -> 193893000000 | F7: =Historicals!C10 -> 225465000000 | G7: =G5*Assumptions!$B$12 -> 2.6379405e+11 | H7: =H5*Assumptions!$B$12 -> 303363157500 | I7: =I5*Assumptions!$B$12 -> 3.4280037e+11 | J7: =J5*Assumptions!$B$12 -> 383936412132 | K7: =K5*Assumptions!$B$12 -> 4.2616942e+11
A8: Gross Margin % | B8: =B7/B5 -> 0.68401674 | C8: =C7/C5 -> 0.68920086 | D8: =D7/D5 -> 0.69764444 | E8: =E7/E5 -> 0.68823742 | F8: =F7/F5 -> 0.67944093 | G8: =G7/G5 -> 0.67944093 | H8: =H7/H5 -> 0.67944093 | I8: =I7/I5 -> 0.67944093 | ... K8: =K7/K5 -> 0.67944093
A9: EBIT | B9: =Historicals!D6 -> 83383000000 | C9: =Historicals!D7 -> 88523000000 | D9: =Historicals!D8 -> 109433000000 | E9: =Historicals!D9 -> 128528000000 | F9: =Historicals!D10 -> 155237000000 | G9: =G5*Assumptions!$B$13 -> 181627290000 | H9: =H5*Assumptions!$B$13 -> 2.0887138e+11 | I9: =I5*Assumptions!$B$13 -> 2.3602466e+11 | J9: =J5*Assumptions!$B$13 -> 2.6434762e+11 | K9: =K5*Assumptions!$B$13 -> 2.9342586e+11
A10: EBIT Margin % | B10: =B9/B5 -> 0.42055278 | C10: =C9/C5 -> 0.41772881 | D10: =D9/D5 -> 0.446443 | E10: =E9/E5 -> 0.45621956 | F10: =F9/F5 -> 0.46780818 | G10: =G9/G5 -> 0.46780818 | H10: =H9/H5 -> 0.46780818 | I10: =I9/I5 -> 0.46780818 | ... K10: =K9/K5 -> 0.46780818
A12: Free Cash Flow Build | B12: FY2022 | C12: FY2023 | D12: FY2024 | E12: FY2025 | F12: FY2026 | G12: FY2027E | H12: FY2028E | I12: FY2029E | J12: FY2030E | K12: FY2031E
A13: NOPAT (EBIT after Tax) | B13: =B9*(1-Historicals!H6) -> 7.2448668e+10 | C13: =C9*(1-Historicals!H7) -> 7.1722552e+10 | D13: =D9*(1-Historicals!H8) -> 8.9481912e+10 | E13: =E9*(1-Historicals!H9) -> 1.0586897e+11 | F13: =F9*(1-Historicals!H10) -> 1.2512682e+11 | G13: =G9*(1-Assumptions!$B$14) -> 1.4639838e+11 | H13: =H9*(1-Assumptions!$B$14) -> 1.6835813e+11 | I13: =I9*(1-Assumptions!$B$14) -> 1.9024469e+11 | J13: =J9*(1-Assumptions!$B$14) -> 2.1307405e+11 | K13: =K9*(1-Assumptions!$B$14) -> 2.365122e+11
A14: Plus: D&A | B14: =Historicals!I6 -> 14460000000 | C14: =Historicals!I7 -> 13861000000 | D14: =Historicals!I8 -> 20958000000 | E14: =Historicals!I9 -> 29433000000 | F14: =Historicals!I10 -> 38534000000 | G14: =G5*Assumptions!$B$17 -> 3.9614278e+10 | H14: =H5*Assumptions!$B$17 -> 4.555642e+10 | I14: =I5*Assumptions!$B$17 -> 5.1478754e+10 | J14: =J5*Assumptions!$B$17 -> 5.7656205e+10 | K14: =K5*Assumptions!$B$17 -> 6.3998387e+10
A15: Less: CapEx | B15: =Historicals!J6 -> 23886000000 | C15: =Historicals!J7 -> 28107000000 | D15: =Historicals!J8 -> 44477000000 | E15: =Historicals!J9 -> 64551000000 | F15: =Historicals!J10 -> 115948000000 | G15: =G5*Assumptions!$B$18 -> 116475489000 | H15: =H5*Assumptions!$C$18 -> 1.0715745e+11 | I15: =I5*Assumptions!$D$18 -> 9.0815939e+10 | J15: =J5*Assumptions!$E$18 -> 7.9110773e+10 | K15: =K5*Assumptions!$F$18 -> 6.8995896e+10
A16: Less: Change in NWC | B16: =Historicals!N6-Historicals!N5 -> -21147000000 | C16: =Historicals!N7-Historicals!N6 -> 5506000000 | D16: =Historicals!N8-Historicals!N7 -> -45660000000 | E16: =Historicals!N9-Historicals!N8 -> 15465000000 | F16: =Historicals!N10-Historicals!N9 -> -11028000000 | G16: =(G5-F5)*Assumptions!$B$19 -> 1692378900 | H16: =(H5-G5)*Assumptions!$B$19 -> 1.7471323e+09 | I16: =(I5-H5)*Assumptions!$B$19 -> 1.7413086e+09 | J16: =(J5-I5)*Assumptions!$B$19 -> 1.8163188e+09 | K16: =(K5-J5)*Assumptions!$B$19 -> 1.8647539e+09
A18: FCFF | B18: =B13 + B14 - B15 - B16 -> 8.4169668e+10 | C18: =C13 + C14 - C15 - C16 -> 5.1970552e+10 | D18: =D13 + D14 - D15 - D16 -> 1.1162291e+11 | E18: =E13 + E14 - E15 - E16 -> 5.5285971e+10 | F18: =F13 + F14 - F15 - F16 -> 5.8740819e+10 | G18: =G13 + G14 - G15 - G16 -> 6.7844788e+10 | H18: =H13 + H14 - H15 - H16 -> 1.0500997e+11 | I18: =I13 + I14 - I15 - I16 -> 1.491662e+11 | ... K18: =K13 + K14 - K15 - K16 -> 2.2964994e+11

Sheet DCF
A1: MSFT DCF Model - DCF
A2: Values in USD - fiscal year ending June 30
A5: Forecast Year | B5: FY2027E | C5: FY2028E | D5: FY2029E | E5: FY2030E | F5: FY2031E
A6: Discount Period | B6: =Assumptions!$B$42 -> 0.67671233 | C6: =B6+1 -> 1.6767123 | D6: =C6+1 -> 2.6767123 | E6: =D6+1 -> 3.6767123 | F6: =E6+1 -> 4.6767123
A7: FCFF (FY2027E pro-rated to stub) | B7: =Forecast!G18*Assumptions!$B$42 -> 4.5911404e+10 | C7: =Forecast!H18 -> 1.0500997e+11 | D7: =Forecast!I18 -> 1.491662e+11 | E7: =Forecast!J18 -> 1.8980317e+11 | F7: =Forecast!K18 -> 2.2964994e+11
A8: Discount Factor | B8: =1/(1+Assumptions!$B$30)^B6 -> 0.94074756 | C8: =1/(1+Assumptions!$B$30)^C6 -> 0.85955452 | D8: =1/(1+Assumptions!$B$30)^D6 -> 0.785369 | E8: =1/(1+Assumptions!$B$30)^E6 -> 0.71758621 | F8: =1/(1+Assumptions!$B$30)^F6 -> 0.65565355
A9: PV of FCFF | B9: =B7*B8 -> 4.3191042e+10 | C9: =C7*C8 -> 9.0261796e+10 | D9: =D7*D8 -> 1.1715051e+11 | E9: =E7*E8 -> 1.3620014e+11 | F9: =F7*F8 -> 1.505708e+11
A11: Sum of PV (FCFF) | B11: =SUM(B9:F9) -> 5.3737428e+11
A13: Terminal Year FCFF (FY2032E) | B13: =Forecast!K18*(1+Assumptions!$B$33) -> 2.3653944e+11
A14: Terminal Value | B14: =B13/(Assumptions!B30-Assumptions!B33) -> 3.6695857e+12
A15: PV of Terminal Value | B15: =B14/(1+Assumptions!$B$30)^F6 -> 2.4059769e+12
A17: Enterprise Value | B17: =B11+B15 -> 2.9433512e+12
A20: Less: Total Debt incl. Finance Leases | B20: =Assumptions!B47 -> 106888000000
A21: Plus: Cash & Short-Term Investments | B21: =Assumptions!B48 -> 76843000000
A22: Plus: Long-Term Equity Investments | B22: =Assumptions!B49 -> 36348000000
A23: Equity Value | B23: =B17-B20+B21+B22 -> 2.9496542e+12
A24: Diluted Shares Outstanding | B24: =Assumptions!$B$36 -> 7449545491
A25: Intrinsic Value Per Share | B25: =B23/B24 -> 395.95089
A26: Current Stock Price | B26: =Assumptions!$B$37 -> 532.6
A27: Implied Upside / Downside | B27: =(B25-B26)/B26 -> -0.25656986

Sheet Sensitivity
A1: MSFT DCF Model - Sensitivity
A2: Values in USD - fiscal year ending June 30
A3: Sensitivity Analysis: Intrinsic Value Per Share (USD)
A4: ="WACC vs. Terminal Growth Rate | Base Case: "&TEXT(DCF!B25,"$0.00")&" | Current Price: "&TEXT(Assumptions!B37,"$0.00") -> WACC vs. Terminal Growth Rate | Base Case: $395.95 | Current Price: $532.60
D7: TERMINAL GROWTH RATE →
B8: =DCF!B25 -> 395.95089 | C8: 0.02 | D8: 0.025 | E8: 0.03 | F8: 0.035 | G8: 0.04
A9: WACC ↓ | B9: 0.08 | C9: =(SUMPRODUCT(DCF!$B$7:$F$7/(1+$B9)^DCF!$B$6:$F$6)+DCF!$F$7*(1+C$8)/($B9-C$8)/(1+$B9)^DCF!$F$6-DCF!$B$20+DCF!$B$21+DCF!$B$22)/DCF!$B$24 -> 441.74569 | D9: =(SUMPRODUCT(DCF!$B$7:$F$7/(1+$B9)^DCF!$B$6:$F$6)+DCF!$F$7*(1+D$8)/($B9-D$8)/(1+$B9)^DCF!$F$6-DCF!$B$20+DCF!$B$21+DCF!$B$22)/DCF!$B$24 -> 476.94248 | E9: =(SUMPRODUCT(DCF!$B$7:$F$7/(1+$B9)^DCF!$B$6:$F$6)+DCF!$F$7*(1+E$8)/($B9-E$8)/(1+$B9)^DCF!$F$6-DCF!$B$20+DCF!$B$21+DCF!$B$22)/DCF!$B$24 -> 519.17863 | F9: =(SUMPRODUCT(DCF!$B$7:$F$7/(1+$B9)^DCF!$B$6:$F$6)+DCF!$F$7*(1+F$8)/($B9-F$8)/(1+$B9)^DCF!$F$6-DCF!$B$20+DCF!$B$21+DCF!$B$22)/DCF!$B$24 -> 570.8006 | G9: =(SUMPRODUCT(DCF!$B$7:$F$7/(1+$B9)^DCF!$B$6:$F$6)+DCF!$F$7*(1+G$8)/($B9-G$8)/(1+$B9)^DCF!$F$6-DCF!$B$20+DCF!$B$21+DCF!$B$22)/DCF!$B$24 -> 635.32805
B10: 0.085 | C10: =(SUMPRODUCT(DCF!$B$7:$F$7/(1+$B10)^DCF!$B$6:$F$6)+DCF!$F$7*(1+C$8)/($B10-C$8)/(1+$B10)^DCF!$F$6-DCF!$B$20+DCF!$B$21+DCF!$B$22)/DCF!$B$24 -> 405.30839 | D10: =(SUMPRODUCT(DCF!$B$7:$F$7/(1+$B10)^DCF!$B$6:$F$6)+DCF!$F$7*(1+D$8)/($B10-D$8)/(1+$B10)^DCF!$F$6-DCF!$B$20+DCF!$B$21+DCF!$B$22)/DCF!$B$24 -> 434.58879 | E10: =(SUMPRODUCT(DCF!$B$7:$F$7/(1+$B10)^DCF!$B$6:$F$6)+DCF!$F$7*(1+E$8)/($B10-E$8)/(1+$B10)^DCF!$F$6-DCF!$B$20+DCF!$B$21+DCF!$B$22)/DCF!$B$24 -> 469.1929 | F10: =(SUMPRODUCT(DCF!$B$7:$F$7/(1+$B10)^DCF!$B$6:$F$6)+DCF!$F$7*(1+F$8)/($B10-F$8)/(1+$B10)^DCF!$F$6-DCF!$B$20+DCF!$B$21+DCF!$B$22)/DCF!$B$24 -> 510.71783 | G10: =(SUMPRODUCT(DCF!$B$7:$F$7/(1+$B10)^DCF!$B$6:$F$6)+DCF!$F$7*(1+G$8)/($B10-G$8)/(1+$B10)^DCF!$F$6-DCF!$B$20+DCF!$B$21+DCF!$B$22)/DCF!$B$24 -> 561.47053
B11: 0.09 | C11: =(SUMPRODUCT(DCF!$B$7:$F$7/(1+$B11)^DCF!$B$6:$F$6)+DCF!$F$7*(1+C$8)/($B11-C$8)/(1+$B11)^DCF!$F$6-DCF!$B$20+DCF!$B$21+DCF!$B$22)/DCF!$B$24 -> 374.11609 | D11: =(SUMPRODUCT(DCF!$B$7:$F$7/(1+$B11)^DCF!$B$6:$F$6)+DCF!$F$7*(1+D$8)/($B11-D$8)/(1+$B11)^DCF!$F$6-DCF!$B$20+DCF!$B$21+DCF!$B$22)/DCF!$B$24 -> 398.79288 | E11: =(SUMPRODUCT(DCF!$B$7:$F$7/(1+$B11)^DCF!$B$6:$F$6)+DCF!$F$7*(1+E$8)/($B11-E$8)/(1+$B11)^DCF!$F$6-DCF!$B$20+DCF!$B$21+DCF!$B$22)/DCF!$B$24 -> 427.58247 | F11: =(SUMPRODUCT(DCF!$B$7:$F$7/(1+$B11)^DCF!$B$6:$F$6)+DCF!$F$7*(1+F$8)/($B11-F$8)/(1+$B11)^DCF!$F$6-DCF!$B$20+DCF!$B$21+DCF!$B$22)/DCF!$B$24 -> 461.60653 | G11: =(SUMPRODUCT(DCF!$B$7:$F$7/(1+$B11)^DCF!$B$6:$F$6)+DCF!$F$7*(1+G$8)/($B11-G$8)/(1+$B11)^DCF!$F$6-DCF!$B$20+DCF!$B$21+DCF!$B$22)/DCF!$B$24 -> 502.43541
B12: 0.095 | C12: =(SUMPRODUCT(DCF!$B$7:$F$7/(1+$B12)^DCF!$B$6:$F$6)+DCF!$F$7*(1+C$8)/($B12-C$8)/(1+$B12)^DCF!$F$6-DCF!$B$20+DCF!$B$21+DCF!$B$22)/DCF!$B$24 -> 347.11896 | D12: =(SUMPRODUCT(DCF!$B$7:$F$7/(1+$B12)^DCF!$B$6:$F$6)+DCF!$F$7*(1+D$8)/($B12-D$8)/(1+$B12)^DCF!$F$6-DCF!$B$20+DCF!$B$21+DCF!$B$22)/DCF!$B$24 -> 368.14865 | E12: =(SUMPRODUCT(DCF!$B$7:$F$7/(1+$B12)^DCF!$B$6:$F$6)+DCF!$F$7*(1+E$8)/($B12-E$8)/(1+$B12)^DCF!$F$6-DCF!$B$20+DCF!$B$21+DCF!$B$22)/DCF!$B$24 -> 392.41368 | F12: =(SUMPRODUCT(DCF!$B$7:$F$7/(1+$B12)^DCF!$B$6:$F$6)+DCF!$F$7*(1+F$8)/($B12-F$8)/(1+$B12)^DCF!$F$6-DCF!$B$20+DCF!$B$21+DCF!$B$22)/DCF!$B$24 -> 420.72287 | G12: =(SUMPRODUCT(DCF!$B$7:$F$7/(1+$B12)^DCF!$B$6:$F$6)+DCF!$F$7*(1+G$8)/($B12-G$8)/(1+$B12)^DCF!$F$6-DCF!$B$20+DCF!$B$21+DCF!$B$22)/DCF!$B$24 -> 454.1792
B13: 0.1 | C13: =(SUMPRODUCT(DCF!$B$7:$F$7/(1+$B13)^DCF!$B$6:$F$6)+DCF!$F$7*(1+C$8)/($B13-C$8)/(1+$B13)^DCF!$F$6-DCF!$B$20+DCF!$B$21+DCF!$B$22)/DCF!$B$24 -> 323.52965 | D13: =(SUMPRODUCT(DCF!$B$7:$F$7/(1+$B13)^DCF!$B$6:$F$6)+DCF!$F$7*(1+D$8)/($B13-D$8)/(1+$B13)^DCF!$F$6-DCF!$B$20+DCF!$B$21+DCF!$B$22)/DCF!$B$24 -> 341.62498 | E13: =(SUMPRODUCT(DCF!$B$7:$F$7/(1+$B13)^DCF!$B$6:$F$6)+DCF!$F$7*(1+E$8)/($B13-E$8)/(1+$B13)^DCF!$F$6-DCF!$B$20+DCF!$B$21+DCF!$B$22)/DCF!$B$24 -> 362.30534 | F13: =(SUMPRODUCT(DCF!$B$7:$F$7/(1+$B13)^DCF!$B$6:$F$6)+DCF!$F$7*(1+F$8)/($B13-F$8)/(1+$B13)^DCF!$F$6-DCF!$B$20+DCF!$B$21+DCF!$B$22)/DCF!$B$24 -> 386.16731 | G13: =(SUMPRODUCT(DCF!$B$7:$F$7/(1+$B13)^DCF!$B$6:$F$6)+DCF!$F$7*(1+G$8)/($B13-G$8)/(1+$B13)^DCF!$F$6-DCF!$B$20+DCF!$B$21+DCF!$B$22)/DCF!$B$24 -> 414.00626
B14: 0.105 | C14: =(SUMPRODUCT(DCF!$B$7:$F$7/(1+$B14)^DCF!$B$6:$F$6)+DCF!$F$7*(1+C$8)/($B14-C$8)/(1+$B14)^DCF!$F$6-DCF!$B$20+DCF!$B$21+DCF!$B$22)/DCF!$B$24 -> 302.74611 | D14: =(SUMPRODUCT(DCF!$B$7:$F$7/(1+$B14)^DCF!$B$6:$F$6)+DCF!$F$7*(1+D$8)/($B14-D$8)/(1+$B14)^DCF!$F$6-DCF!$B$20+DCF!$B$21+DCF!$B$22)/DCF!$B$24 -> 318.44854 | E14: =(SUMPRODUCT(DCF!$B$7:$F$7/(1+$B14)^DCF!$B$6:$F$6)+DCF!$F$7*(1+E$8)/($B14-E$8)/(1+$B14)^DCF!$F$6-DCF!$B$20+DCF!$B$21+DCF!$B$22)/DCF!$B$24 -> 336.24464 | F14: =(SUMPRODUCT(DCF!$B$7:$F$7/(1+$B14)^DCF!$B$6:$F$6)+DCF!$F$7*(1+F$8)/($B14-F$8)/(1+$B14)^DCF!$F$6-DCF!$B$20+DCF!$B$21+DCF!$B$22)/DCF!$B$24 -> 356.58303 | G14: =(SUMPRODUCT(DCF!$B$7:$F$7/(1+$B14)^DCF!$B$6:$F$6)+DCF!$F$7*(1+G$8)/($B14-G$8)/(1+$B14)^DCF!$F$6-DCF!$B$20+DCF!$B$21+DCF!$B$22)/DCF!$B$24 -> 380.05041

Sheet Summary
A1: MSFT DCF Model - Summary
A2: Values in USD - fiscal year ending June 30
A3: ="Valuation date: "&TEXT(Assumptions!B40,"mm/dd/yyyy") -> Valuation date: 10/26/2026
A4: COMPANY OVERVIEW
A5: Company | Microsoft Corporation
A6: Sector | Technology
A7: ="Market Cap | "&TEXT(Profile!B7/1000000000000,"$0.00")&"T" -> Market Cap | $3.95T
A8: ="Current Price | "&TEXT(Assumptions!B37,"$0.00") -> Current Price | $532.60
A10: VALUATION SUMMARY
A11: ="Intrinsic Value Per Share | "&TEXT(DCF!B25,"$0.00") -> Intrinsic Value Per Share | $395.95
A12: ="Current Market Price | "&TEXT(Assumptions!B37,"$0.00") -> Current Market Price | $532.60
A13: ="Implied Upside / Downside | "&TEXT(DCF!B27,"0.00%") -> Implied Upside / Downside | -25.66%
A14: Recommendation | Small long position, long-term horizon
A16: KEY ASSUMPTIONS
A17: ="WACC | "&TEXT(Assumptions!B30,"0.00%") -> WACC | 9.45%
A18: ="Terminal Growth Rate | "&TEXT(Assumptions!B33,"0.00%") -> Terminal Growth Rate | 3.00%
A19: Projection Period | FY2027E - FY2031E
A20: ="FY2031E Revenue | "&TEXT(Forecast!K5/1000000000,"$#,##0.0")&"B" -> FY2031E Revenue | $627.2B
A22: INVESTMENT THESIS
A23: Upside | Copilot/Azure AI adoption faster than modeled
A24: Downside | AI CapEx doesn't translate to revenue growth
A25: View | Market pricing in more optimism than base case justifies
